Workbook
Name ___BOP2: [1]BoP!#REF!
Name ___BOP2: [1]BoP!#REF!
Name ___BOP2: [1]BoP!#REF!
Name ___BOP2: [1]BoP!#REF!
Name ___EXP5: #REF!
Name ___EXP5: #REF!
Name ___EXP5: #REF!
Name ___EXP5: #REF!
Name ___EXP6: #REF!
Name ___EXP6: #REF!
Name ___EXP6: #REF!
Name ___EXP6: #REF!
Name ___EXP7: #REF!
Name ___EXP7: #REF!
Name ___EXP7: #REF!
Name ___EXP7: #REF!
Name ___EXP9: #REF!
Name ___EXP9: #REF!
Name ___EXP9: #REF!
Name ___EXP9: #REF!
Name ___IMP2: #REF!
Name ___IMP2: #REF!
Name ___IMP2: #REF!
Name ___IMP2: #REF!
Name ___IMP4: #REF!
Name ___IMP4: #REF!
Name ___IMP4: #REF!
Name ___IMP4: #REF!
Name ___IMP6: #REF!
Name ___IMP6: #REF!
Name ___IMP6: #REF!
Name ___IMP6: #REF!
Name ___IMP7: #REF!
Name ___IMP7: #REF!
Name ___IMP7: #REF!
Name ___IMP7: #REF!
Name ___MTS2: '[2]Annual Tables'!#REF!
Name ___MTS2: '[2]Annual Tables'!#REF!
Name ___MTS2: '[2]Annual Tables'!#REF!
Name ___MTS2: '[2]Annual Tables'!#REF!
Name ___PAG2: [2]Index!#REF!
Name ___PAG2: [2]Index!#REF!
Name ___PAG2: [2]Index!#REF!
Name ___PAG2: [2]Index!#REF!
Name ___PAG3: [2]Index!#REF!
Name ___PAG3: [2]Index!#REF!
Name ___PAG3: [2]Index!#REF!
Name ___PAG3: [2]Index!#REF!
Name ___PAG4: [2]Index!#REF!
Name ___PAG4: [2]Index!#REF!
Name ___PAG4: [2]Index!#REF!
Name ___PAG4: [2]Index!#REF!
Name ___PAG5: [2]Index!#REF!
Name ___PAG5: [2]Index!#REF!
Name ___PAG5: [2]Index!#REF!
Name ___PAG5: [2]Index!#REF!
Name ___PAG6: [2]Index!#REF!
Name ___PAG6: [2]Index!#REF!
Name ___PAG6: [2]Index!#REF!
Name ___PAG6: [2]Index!#REF!

Sheet Debt Dynamics
B2: Fiscal Sustainability
B4: Debt Sustinability Analysis
B7: Debt Dynamics
D8: Actual | G8: Projections
B9: Assumptions | D9: 2016 | E9: 2017 | F9: 2018 | G9: 2019 | H9: 2020 | I9: 2021 | J9: 2022
B11: Growth of GDP (%) | C11: g | D11: 2.3023979 | E11: =D11 -> 2.3023979 | F11: =E11 -> 2.3023979 | G11: =F11 -> 2.3023979 | H11: =G11 -> 2.3023979 | I11: =H11 -> 2.3023979 | J11: =I11 -> 2.3023979
B12: Effective nominal domestic interest rate (%) | C12: i | D12: 6.8796799 | E12: =D12 -> 6.8796799 | F12: =E12 -> 6.8796799 | G12: =F12 -> 6.8796799 | H12: =G12 -> 6.8796799 | I12: =H12 -> 6.8796799 | J12: =I12 -> 6.8796799
B13: Inflation (%) (GDP deflator) | C13: π | D13: 13.64 | E13: =D13 -> 13.64 | F13: =E13 -> 13.64 | G13: =F13 -> 13.64 | H13: =G13 -> 13.64 | I13: =H13 -> 13.64 | J13: =I13 -> 13.64
B14: Effective nominal foreign interest rate (%) | C14: if | D14: 5.3251739 | E14: =D14 -> 5.3251739 | F14: =E14 -> 5.3251739 | G14: =F14 -> 5.3251739 | H14: =G14 -> 5.3251739 | I14: =H14 -> 5.3251739 | J14: =I14 -> 5.3251739
B15: Exchange rate depreciation (%) | C15: ε | D15: 20.485863 | E15: 3 | F15: =E15 -> 3 | G15: =F15 -> 3 | H15: =G15 -> 3 | I15: =H15 -> 3 | J15: =I15 -> 3
B16: Share of foreign currency debt (% of total) | C16: α | D16: 27 | E16: =D16 -> 27 | F16: =E16 -> 27 | G16: =F16 -> 27 | H16: =G16 -> 27 | I16: =H16 -> 27 | J16: =I16 -> 27
B17: Effective real domestic interest rate (%) | C17: r | D17: 2.1678297 | E17: =((1+E12%)/(1+E13%)-1)*100 -> -5.9488913 | F17: =E17 -> -5.9488913 | G17: =F17 -> -5.9488913 | H17: =G17 -> -5.9488913 | I17: =H17 -> -5.9488913 | J17: =I17 -> -5.9488913
B18: Effective real foreign interest rate (%) | C18: rf | D18: 21.307402 | E18: =(((1+E14%)*(1+E15%))/(1+E13%)-1)*100 -> -4.5363172 | F18: =(((1+F14%)*(1+F15%))/(1+F13%)-1)*100 -> -4.5363172 | G18: =(((1+G14%)*(1+G15%))/(1+G13%)-1)*100 -> -4.5363172 | H18: =(((1+H14%)*(1+H15%))/(1+H13%)-1)*100 -> -4.5363172 | I18: =(((1+I14%)*(1+I15%))/(1+I13%)-1)*100 -> -4.5363172 | J18: =(((1+J14%)*(1+J15%))/(1+J13%)-1)*100 -> -4.5363172
B19: Weighted average interest rate (%) | C19: rw | D19: 7.3355141 | E19: =(D16%*E18%+(1-D16%)*E17%)*100 -> -5.5674963 | F19: =(E16%*F18%+(1-E16%)*F17%)*100 -> -5.5674963 | G19: =(F16%*G18%+(1-F16%)*G17%)*100 -> -5.5674963 | H19: =(G16%*H18%+(1-G16%)*H17%)*100 -> -5.5674963 | I19: =(H16%*I18%+(1-H16%)*I17%)*100 -> -5.5674963 | J19: =(I16%*J18%+(1-I16%)*J17%)*100 -> -5.5674963
B20: Primary balance (% of GDP) | C20: pb | D20: 0.050572024 | E20: =D20 -> 0.050572024 | F20: =E20 -> 0.050572024 | G20: =F20 -> 0.050572024 | H20: =G20 -> 0.050572024 | I20: =H20 -> 0.050572024 | J20: =I20 -> 0.050572024
B21: Public debt (% of GDP) | C21: d | D21: 58.096 | E21: =((1+E19%)/(1+E11%)*D21%-E20%)*100 -> 53.576233 | F21: =((1+F19%)/(1+F11%)*E21%-F20%)*100 -> 49.404161 | G21: =((1+G19%)/(1+G11%)*F21%-G20%)*100 -> 45.553038 | H21: =((1+H19%)/(1+H11%)*G21%-H20%)*100 -> 41.998173 | I21: =((1+I19%)/(1+I11%)*H21%-I20%)*100 -> 38.716775 | J21: =((1+J19%)/(1+J11%)*I21%-J20%)*100 -> 35.687808

Sheet Stabilizing Debt
B2: Fiscal Sustainability
B4: Debt Sustinability Analysis
B7: Debt Dynamics
D8: Actual | G8: Projections
B9: Assumptions | D9: 2016 | E9: 2017 | F9: 2018 | G9: 2019 | H9: 2020 | I9: 2021 | J9: 2022
B11: Growth of GDP (%) | C11: g | D11: 2.3023979 | E11: =D11 -> 2.3023979 | F11: =E11 -> 2.3023979 | G11: =F11 -> 2.3023979 | H11: =G11 -> 2.3023979 | I11: =H11 -> 2.3023979 | J11: =I11 -> 2.3023979
B12: Effective nominal domestic interest rate (%) | C12: i | D12: 6.8796799 | E12: =D12 -> 6.8796799 | F12: =E12 -> 6.8796799 | G12: =F12 -> 6.8796799 | H12: =G12 -> 6.8796799 | I12: =H12 -> 6.8796799 | J12: =I12 -> 6.8796799
B13: Inflation (%) (GDP deflator) | C13: π | D13: 4.6118726 | E13: =D13 -> 4.6118726 | F13: =E13 -> 4.6118726 | G13: =F13 -> 4.6118726 | H13: =G13 -> 4.6118726 | I13: =H13 -> 4.6118726 | J13: =I13 -> 4.6118726
B14: Effective nominal foreign interest rate (%) | C14: if | D14: 5.3251739 | E14: =D14 -> 5.3251739 | F14: =E14 -> 5.3251739 | G14: =F14 -> 5.3251739 | H14: =G14 -> 5.3251739 | I14: =H14 -> 5.3251739 | J14: =I14 -> 5.3251739
B15: Exchange rate depreciation (%) | C15: ε | D15: 20.485863 | E15: 3 | F15: =E15 -> 3 | G15: =F15 -> 3 | H15: =G15 -> 3 | I15: =H15 -> 3 | J15: =I15 -> 3
B16: Share of foreign currency debt (% of total) | C16: α | D16: 27 | E16: =D16 -> 27 | F16: =E16 -> 27 | G16: =F16 -> 27 | H16: =G16 -> 27 | I16: =H16 -> 27 | J16: =I16 -> 27
B17: Effective real domestic interest rate (%) | C17: r | D17: 2.1678297 | E17: =((1+E12%)/(1+E13%)-1)*100 -> 2.1678297 | F17: =((1+F12%)/(1+F13%)-1)*100 -> 2.1678297 | G17: =((1+G12%)/(1+G13%)-1)*100 -> 2.1678297 | H17: =((1+H12%)/(1+H13%)-1)*100 -> 2.1678297 | I17: =((1+I12%)/(1+I13%)-1)*100 -> 2.1678297 | J17: =((1+J12%)/(1+J13%)-1)*100 -> 2.1678297
B18: Effective real foreign interest rate (%) | C18: rf | D18: 21.307402 | E18: =(((1+E14%)*(1+E15%))/(1+E13%)-1)*100 -> 3.7023106 | F18: =(((1+F14%)*(1+F15%))/(1+F13%)-1)*100 -> 3.7023106 | G18: =(((1+G14%)*(1+G15%))/(1+G13%)-1)*100 -> 3.7023106 | H18: =(((1+H14%)*(1+H15%))/(1+H13%)-1)*100 -> 3.7023106 | I18: =(((1+I14%)*(1+I15%))/(1+I13%)-1)*100 -> 3.7023106 | J18: =(((1+J14%)*(1+J15%))/(1+J13%)-1)*100 -> 3.7023106
B19: Weigted average interest rate (%) | C19: rw | D19: 7.3355141 | E19: =((1-D16%)*E17%+D16%*E18%)*100 -> 2.5821395 | F19: =((1-E16%)*F17%+E16%*F18%)*100 -> 2.5821395 | G19: =((1-F16%)*G17%+F16%*G18%)*100 -> 2.5821395 | H19: =((1-G16%)*H17%+G16%*H18%)*100 -> 2.5821395 | I19: =((1-H16%)*I17%+H16%*I18%)*100 -> 2.5821395 | J19: =((1-I16%)*J17%+I16%*J18%)*100 -> 2.5821395
B20: Primary balance (% of GDP) | C20: pb | D20: 0.050572024 | E20: =$D$24 -> 0.15886106 | F20: =$D$24 -> 0.15886106 | G20: =$D$24 -> 0.15886106 | H20: =$D$24 -> 0.15886106 | I20: =$D$24 -> 0.15886106 | J20: =$D$24 -> 0.15886106
B21: Public debt (% of GDP) | C21: d | D21: 58.096 | E21: =((1+E19%)/(1+E11%)*D21%-E20%)*100 -> 58.096 | F21: =((1+F19%)/(1+F11%)*E21%-F20%)*100 -> 58.096 | G21: =((1+G19%)/(1+G11%)*F21%-G20%)*100 -> 58.096 | H21: =((1+H19%)/(1+H11%)*G21%-H20%)*100 -> 58.096 | I21: =((1+I19%)/(1+I11%)*H21%-I20%)*100 -> 58.096 | J21: =((1+J19%)/(1+J11%)*I21%-J20%)*100 -> 58.096
B23: Debt stabilizing primary balance
B24: Debt stabilizing primary balance | C24: pb* | D24: =(D21%*((1+E19%)/(1+E11%)-1))*100 -> 0.15886106

Sheet Baseline Scenario
B2: Fiscal Sustainability
B4: Debt Sustinability Analysis
B6: Baseline Assumptions | E6: 2017 | F6: 2018 | G6: 2019 | H6: 2020 | I6: 2021 | J6: 2022
B7: Growth of GDP (%) | E7: 1.7 | F7: 2 | G7: 2.2 | H7: 2.3 | I7: 2.3 | J7: 2.3
B8: Effective nominal domestic interest rate (%) | E8: 6.9 | F8: 7.2 | G8: 6.5 | H8: 6.5 | I8: 6.5 | J8: 6.5
B9: Inflation (%) (GDP deflator) | E9: 4.6 | F9: 4.5 | G9: 4.3 | H9: 4.2 | I9: 4 | J9: 4
B10: Effective nominal foreign interest rate (%) | E10: 5.3 | F10: 5.3 | G10: 5.5 | H10: 5.5 | I10: 5.6 | J10: 5.6
B11: Exchange rate depreciation (%) | E11: 3 | F11: 3 | G11: 3 | H11: 3 | I11: 3 | J11: 3
B12: Primary balance (% of GDP) | E12: 0 | F12: 0.1 | G12: 0.3 | H12: 0.5 | I12: 0.5 | J12: 0.5
B17: Baseline scenario
D18: Actual | G18: Projections
B19: Variables | D19: 2016 | E19: 2017 | F19: 2018 | G19: 2019 | H19: 2020 | I19: 2021 | J19: 2022
B21: Growth of GDP (%) | C21: g | D21: 2.3023979 | E21: 1.7 | F21: 2 | G21: 2.2 | H21: 2.3 | I21: 2.3 | J21: 2.3
B22: Effective nominal domestic interest rate (%) | C22: i | D22: 6.8796799 | E22: 6.9 | F22: 7.2 | G22: 6.5 | H22: 6.5 | I22: 6.5 | J22: 6.5
B23: Inflation (%) (GDP deflator) | C23: π | D23: 4.6118726 | E23: 4.6 | F23: 4.5 | G23: 4.3 | H23: 4.2 | I23: 4 | J23: 4
B24: Effective nominal foreign interest rate (%) | C24: if | D24: 5.3251739 | E24: 5.3 | F24: 5.3 | G24: 5.5 | H24: 5.5 | I24: 5.6 | J24: 5.6
B25: Exchange rate depreciation (%) | C25: ε | D25: 20.485863 | E25: 3 | F25: 3 | G25: 3 | H25: 3 | I25: 3 | J25: 3
B26: Share of foreign currency debt (% of total) | C26: α | D26: 27 | E26: =D26 -> 27 | F26: =E26 -> 27 | G26: =F26 -> 27 | H26: =G26 -> 27 | I26: =H26 -> 27 | J26: =I26 -> 27
B27: Effective real domestic interest rate (%) | C27: r | D27: 2.1678297 | E27: =((1+E22%)/(1+E23%)-1)*100 -> 2.1988528 | F27: =((1+F22%)/(1+F23%)-1)*100 -> 2.5837321 | G27: =((1+G22%)/(1+G23%)-1)*100 -> 2.1093001 | H27: =((1+H22%)/(1+H23%)-1)*100 -> 2.2072937 | I27: =((1+I22%)/(1+I23%)-1)*100 -> 2.4038462 | J27: =((1+J22%)/(1+J23%)-1)*100 -> 2.4038462
B28: Effective real foreign interest rate (%) | C28: rf | D28: 21.307402 | E28: =(((1+E24%)*(1+E25%))/(1+E23%)-1)*100 -> 3.6892925 | F28: =(((1+F24%)*(1+F25%))/(1+F23%)-1)*100 -> 3.7885167 | G28: =(((1+G24%)*(1+G25%))/(1+G23%)-1)*100 -> 4.1850431 | H28: =(((1+H24%)*(1+H25%))/(1+H23%)-1)*100 -> 4.2850288 | I28: =(((1+I24%)*(1+I25%))/(1+I23%)-1)*100 -> 4.5846154 | J28: =(((1+J24%)*(1+J25%))/(1+J23%)-1)*100 -> 4.5846154
B29: Weigted average interest rate (%) | C29: rw | D29: 7.3355141 | E29: =((1-D26%)*E27%+D26%*E28%)*100 -> 2.6012715 | F29: =((1-E26%)*F27%+E26%*F28%)*100 -> 2.9090239 | G29: =((1-F26%)*G27%+F26%*G28%)*100 -> 2.6697507 | H29: =((1-G26%)*H27%+G26%*H28%)*100 -> 2.7682821 | I29: =((1-H26%)*I27%+H26%*I28%)*100 -> 2.9926538 | J29: =((1-I26%)*J27%+I26%*J28%)*100 -> 2.9926538
B30: Primary balance (% of GDP) | C30: pb | D30: 0.050572024 | E30: 0 | F30: 0.1 | G30: 0.3 | H30: 0.5 | I30: 0.5 | J30: 0.5
B31: Public debt (% of GDP) | C31: d | D31: 58.096 | E31: =((1+E29%)/(1+E21%))*D31-E30 -> 58.61085 | F31: =((1+F29%)/(1+F21%))*E31-F30 -> 59.03319 | G31: =((1+G29%)/(1+G21%))*F31-G30 -> 59.004529 | H31: =((1+H29%)/(1+H21%))*G31-H30 -> 58.774625 | I31: =((1+I29%)/(1+I21%))*H31-I30 -> 58.672577 | J31: =((1+J29%)/(1+J21%))*I31-J30 -> 58.569838

Sheet Stress Tests
B2: Fiscal Sustainability
B4: Debt Sustinability Analysis
B6: Macro-fiscal stress tests
B8: Shocks | C8: Assumptions
B9: 1. GDP growth | C9: -2% in 2017-2018
B10: 2. Interest rates | C10: interest rates (domestic and foreign) go up by 200bps in 2017-2018
B11: 3. Primary balance | C11: primary deficit of 2% of GDP in 2017 and 2018
B12: 4. Exchange rate | C12: exchange rate depreciation by 25% in 2017
B26: GDP Growth Shock
D27: Actual | G27: Projections
B28: Assumptions | D28: 2016 | E28: 2017 | F28: 2018 | G28: 2019 | H28: 2020 | I28: 2021 | J28: 2022
B30: Growth of GDP (%) | C30: g | D30: 2.3023979 | E30: =(D30%-2%)*100 -> 0.30239795 | F30: =(D30%-2%)*100 -> 0.30239795 | G30: ='Baseline Scenario'!G21 -> 2.2 | H30: ='Baseline Scenario'!H21 -> 2.3 | I30: ='Baseline Scenario'!I21 -> 2.3 | J30: ='Baseline Scenario'!J21 -> 2.3
B31: Effective nominal domestic interest rate (%) | C31: i | D31: 6.8796799 | E31: ='Baseline Scenario'!E22 -> 6.9 | F31: ='Baseline Scenario'!F22 -> 7.2 | G31: ='Baseline Scenario'!G22 -> 6.5 | H31: ='Baseline Scenario'!H22 -> 6.5 | I31: ='Baseline Scenario'!I22 -> 6.5 | J31: ='Baseline Scenario'!J22 -> 6.5
B32: Inflation (%) (GDP deflator) | C32: π | D32: 4.6118726 | E32: ='Baseline Scenario'!E23 -> 4.6 | F32: ='Baseline Scenario'!F23 -> 4.5 | G32: ='Baseline Scenario'!G23 -> 4.3 | H32: ='Baseline Scenario'!H23 -> 4.2 | I32: ='Baseline Scenario'!I23 -> 4 | J32: ='Baseline Scenario'!J23 -> 4
B33: Effective nominal foreign interest rate (%) | C33: if | D33: 5.3251739 | E33: ='Baseline Scenario'!E24 -> 5.3 | F33: ='Baseline Scenario'!F24 -> 5.3 | G33: ='Baseline Scenario'!G24 -> 5.5 | H33: ='Baseline Scenario'!H24 -> 5.5 | I33: ='Baseline Scenario'!I24 -> 5.6 | J33: ='Baseline Scenario'!J24 -> 5.6
B34: Exchange rate depreciation (%) | C34: ε | D34: 20.485863 | E34: ='Baseline Scenario'!E25 -> 3 | F34: ='Baseline Scenario'!F25 -> 3 | G34: ='Baseline Scenario'!G25 -> 3 | H34: ='Baseline Scenario'!H25 -> 3 | I34: ='Baseline Scenario'!I25 -> 3 | J34: ='Baseline Scenario'!J25 -> 3
B35: Share of foreign currency debt (% of total) | C35: α | D35: 27 | E35: =D35 -> 27 | F35: =E35 -> 27 | G35: =F35 -> 27 | H35: =G35 -> 27 | I35: =H35 -> 27 | J35: =I35 -> 27
B36: Effective real domestic interest rate (%) | C36: r | D36: 2.1678297 | E36: =((1+E31%)/(1+E32%)-1)*100 -> 2.1988528 | F36: =((1+F31%)/(1+F32%)-1)*100 -> 2.5837321 | G36: =((1+G31%)/(1+G32%)-1)*100 -> 2.1093001 | H36: =((1+H31%)/(1+H32%)-1)*100 -> 2.2072937 | I36: =((1+I31%)/(1+I32%)-1)*100 -> 2.4038462 | J36: =((1+J31%)/(1+J32%)-1)*100 -> 2.4038462
B37: Effective real foreign interest rate (%) | C37: rf | D37: 21.307402 | E37: =(((1+E33%)*(1+E34%))/(1+E32%)-1)*100 -> 3.6892925 | F37: =(((1+F33%)*(1+F34%))/(1+F32%)-1)*100 -> 3.7885167 | G37: =(((1+G33%)*(1+G34%))/(1+G32%)-1)*100 -> 4.1850431 | H37: =(((1+H33%)*(1+H34%))/(1+H32%)-1)*100 -> 4.2850288 | I37: =(((1+I33%)*(1+I34%))/(1+I32%)-1)*100 -> 4.5846154 | J37: =(((1+J33%)*(1+J34%))/(1+J32%)-1)*100 -> 4.5846154
B38: Weigted average interest rate (%) | C38: rw | D38: 7.3355141 | E38: =((1-D35%)*E36%+D35%*E37%)*100 -> 2.6012715 | F38: =((1-E35%)*F36%+E35%*F37%)*100 -> 2.9090239 | G38: =((1-F35%)*G36%+F35%*G37%)*100 -> 2.6697507 | H38: =((1-G35%)*H36%+G35%*H37%)*100 -> 2.7682821 | I38: =((1-H35%)*I36%+H35%*I37%)*100 -> 2.9926538 | J38: =((1-I35%)*J36%+I35%*J37%)*100 -> 2.9926538
B39: Primary balance (% of GDP) | C39: pb | D39: 0.050572024 | E39: ='Baseline Scenario'!E30 -> 0 | F39: ='Baseline Scenario'!F30 -> 0.1 | G39: ='Baseline Scenario'!G30 -> 0.3 | H39: ='Baseline Scenario'!H30 -> 0.5 | I39: ='Baseline Scenario'!I30 -> 0.5 | J39: ='Baseline Scenario'!J30 -> 0.5
B40: Public debt (% of GDP) | C40: d | D40: 58.096 | E40: =((1+E38%)/(1+E30%))*D40-E39 -> 59.427527 | F40: =((1+F38%)/(1+F30%))*E40-F39 -> 60.87191 | G40: =((1+G38%)/(1+G30%))*F40-G39 -> 60.851701 | H40: =((1+H38%)/(1+H30%))*G40-H39 -> 60.630252 | I40: =((1+I38%)/(1+I30%))*H40-I39 -> 60.540768 | J40: =((1+J38%)/(1+J30%))*I40-J39 -> 60.450678
B43: Interest Rate Shock
D44: Actual | G44: Projections
B45: Assumptions | D45: 2016 | E45: 2017 | F45: 2018 | G45: 2019 | H45: 2020 | I45: 2021 | J45: 2022
B47: Growth of GDP (%) | C47: g | D47: 2.3023979 | E47: ='Baseline Scenario'!E21 -> 1.7 | F47: ='Baseline Scenario'!F21 -> 2 | G47: ='Baseline Scenario'!G21 -> 2.2 | H47: ='Baseline Scenario'!H21 -> 2.3 | I47: ='Baseline Scenario'!I21 -> 2.3 | J47: ='Baseline Scenario'!J21 -> 2.3
B48: Effective nominal domestic interest rate (%) | C48: i | D48: 6.8796799 | E48: ='Baseline Scenario'!E22 -> 6.9 | F48: ='Baseline Scenario'!F22 -> 7.2 | G48: ='Baseline Scenario'!G22 -> 6.5 | H48: ='Baseline Scenario'!H22 -> 6.5 | I48: ='Baseline Scenario'!I22 -> 6.5 | J48: ='Baseline Scenario'!J22 -> 6.5
B49: Inflation (%) (GDP deflator) | C49: π | D49: 4.6118726 | E49: ='Baseline Scenario'!E23 -> 4.6 | F49: ='Baseline Scenario'!F23 -> 4.5 | G49: ='Baseline Scenario'!G23 -> 4.3 | H49: ='Baseline Scenario'!H23 -> 4.2 | I49: ='Baseline Scenario'!I23 -> 4 | J49: ='Baseline Scenario'!J23 -> 4
B50: Effective nominal foreign interest rate (%) | C50: if | D50: 5.3251739 | E50: ='Baseline Scenario'!E24 -> 5.3 | F50: ='Baseline Scenario'!F24 -> 5.3 | G50: ='Baseline Scenario'!G24 -> 5.5 | H50: ='Baseline Scenario'!H24 -> 5.5 | I50: ='Baseline Scenario'!I24 -> 5.6 | J50: ='Baseline Scenario'!J24 -> 5.6
B51: Exchange rate depreciation (%) | C51: ε | D51: 20.485863 | E51: ='Baseline Scenario'!E25 -> 3 | F51: ='Baseline Scenario'!F25 -> 3 | G51: ='Baseline Scenario'!G25 -> 3 | H51: ='Baseline Scenario'!H25 -> 3 | I51: ='Baseline Scenario'!I25 -> 3 | J51: ='Baseline Scenario'!J25 -> 3
B52: Share of foreign currency debt (% of total) | C52: α | D52: 27 | E52: =D52 -> 27 | F52: =E52 -> 27 | G52: =F52 -> 27 | H52: =G52 -> 27 | I52: =H52 -> 27 | J52: =I52 -> 27
B53: Effective real domestic interest rate (%) | C53: r | D53: 2.1678297 | E53: =((1+E48%)/(1+E49%)-1)*100 -> 2.1988528 | F53: =((1+F48%)/(1+F49%)-1)*100 -> 2.5837321 | G53: =((1+G48%)/(1+G49%)-1)*100 -> 2.1093001 | H53: =((1+H48%)/(1+H49%)-1)*100 -> 2.2072937 | I53: =((1+I48%)/(1+I49%)-1)*100 -> 2.4038462 | J53: =((1+J48%)/(1+J49%)-1)*100 -> 2.4038462
B54: Effective real foreign interest rate (%) | C54: rf | D54: 21.307402 | E54: =(((1+E50%)*(1+E51%))/(1+E49%)-1)*100 -> 3.6892925 | F54: =(((1+F50%)*(1+F51%))/(1+F49%)-1)*100 -> 3.7885167 | G54: =(((1+G50%)*(1+G51%))/(1+G49%)-1)*100 -> 4.1850431 | H54: =(((1+H50%)*(1+H51%))/(1+H49%)-1)*100 -> 4.2850288 | I54: =(((1+I50%)*(1+I51%))/(1+I49%)-1)*100 -> 4.5846154 | J54: =(((1+J50%)*(1+J51%))/(1+J49%)-1)*100 -> 4.5846154
B55: Weigted average interest rate (%) | C55: rw | D55: 7.3355141 | E55: =((1-D52%)*E53%+D52%*E54%)*100 -> 2.6012715 | F55: =((1-E52%)*F53%+E52%*F54%)*100 -> 2.9090239 | G55: =((1-F52%)*G53%+F52%*G54%)*100 -> 2.6697507 | H55: =((1-G52%)*H53%+G52%*H54%)*100 -> 2.7682821 | I55: =((1-H52%)*I53%+H52%*I54%)*100 -> 2.9926538 | J55: =((1-I52%)*J53%+I52%*J54%)*100 -> 2.9926538
B56: Primary balance (% of GDP) | C56: pb | D56: 0.050572024 | E56: ='Baseline Scenario'!E30 -> 0 | F56: ='Baseline Scenario'!F30 -> 0.1 | G56: ='Baseline Scenario'!G30 -> 0.3 | H56: ='Baseline Scenario'!H30 -> 0.5 | I56: ='Baseline Scenario'!I30 -> 0.5 | J56: ='Baseline Scenario'!J30 -> 0.5
B57: Public debt (% of GDP) | C57: d | D57: 58.096 | E57: =((1+E55%)/(1+E47%))*D57-E56 -> 58.61085 | F57: =((1+F55%)/(1+F47%))*E57-F56 -> 59.03319 | G57: =((1+G55%)/(1+G47%))*F57-G56 -> 59.004529 | H57: =((1+H55%)/(1+H47%))*G57-H56 -> 58.774625 | I57: =((1+I55%)/(1+I47%))*H57-I56 -> 58.672577 | J57: =((1+J55%)/(1+J47%))*I57-J56 -> 58.569838
B60: Primary Balance Shock
D61: Actual | G61: Projections
B62: Assumptions | D62: 2016 | E62: 2017 | F62: 2018 | G62: 2019 | H62: 2020 | I62: 2021 | J62: 2022
B64: Growth of GDP (%) | C64: g | D64: 2.3023979 | E64: ='Baseline Scenario'!E21 -> 1.7 | F64: ='Baseline Scenario'!F21 -> 2 | G64: ='Baseline Scenario'!G21 -> 2.2 | H64: ='Baseline Scenario'!H21 -> 2.3 | I64: ='Baseline Scenario'!I21 -> 2.3 | J64: ='Baseline Scenario'!J21 -> 2.3
...

Sheet Sweden Debt Dynamics
B2: Fiscal Sustainability
B4: Debt Sustinability Analysis
B7: Debt Dynamics
B9: Assumptions | D9: 2019 | E9: 2020 | F9: 2021 | G9: 2022 | H9: 2023 | I9: 2024 | J9: 2025 | K9: 2026 | L9: 2027
B11: Growth of GDP (%) | C11: g | D11: 2.5 | E11: -2 | F11: 5.9 | G11: 1.5 | H11: -0.17 | I11: 0.9 | J11: 2.37 | K11: 2.21 | L11: 2.2
B12: Effective nominal domestic interest rate (%) | C12: i | D12: 0 | E12: 0 | F12: 0 | G12: 2.5 | H12: 4 | I12: 2.75 | J12: 2.25 | K12: 2.25 | L12: 2.25
B13: Inflation (%) (GDP deflator) | C13: π | D13: 2.42 | E13: 1.8 | F13: 2.74063 | G13: 5.78194 | H13: 6.14907 | I13: 2.3 | J13: 1.4 | K13: 1.3 | L13: 1.3
B14: Effective nominal foreign interest rate (%) | C14: if | D14: 2 | E14: 2 | F14: 2 | G14: 2 | H14: 2 | I14: 2 | J14: 2 | K14: 2 | L14: 2
B15: Exchange rate depreciation (%) | C15: ε | D15: 8.121124 | E15: -2.7885403 | F15: -7.2508218 | G15: 15.239993 | H15: 4.6015958 | I15: -0.48734208 | J15: 8.5595671 | K15: 0.68787618 | L15: 0
B16: Share of foreign currency debt (% of total) | C16: α | D16: 2.5 | E16: 2 | F16: 2 | G16: 1.5 | H16: 1.5 | I16: 1.5 | J16: 1 | K16: 0.5 | L16: 0
B17: Effective real domestic interest rate (%) | C17: r | D17: =((1+D12%)/(1+D13%)-1)*100 -> -2.3628198 | E17: =((1+E12%)/(1+E13%)-1)*100 -> -1.7681729 | F17: =((1+F12%)/(1+F13%)-1)*100 -> -2.6675231 | G17: =((1+G12%)/(1+G13%)-1)*100 -> -3.1025523 | H17: =((1+H12%)/(1+H13%)-1)*100 -> -2.0245773 | I17: =((1+I12%)/(1+I13%)-1)*100 -> 0.4398827 | J17: =((1+J12%)/(1+J13%)-1)*100 -> 0.8382643 | K17: =((1+K12%)/(1+K13%)-1)*100 -> 0.93780849 | L17: =((1+L12%)/(1+L13%)-1)*100 -> 0.93780849
B18: Effective real foreign interest rate (%) | C18: rf | D18: =(((1+D14%)*(1+D15%))/(1+D13%)-1)*100 -> 7.677745 | E18: =(((1+E14%)*(1+E15%))/(1+E13%)-1)*100 -> -2.5975551 | F18: =(((1+F14%)*(1+F15%))/(1+F13%)-1)*100 -> -7.9194261 | G18: =(((1+G14%)*(1+G15%))/(1+G13%)-1)*100 -> 11.119906 | H18: =(((1+H14%)*(1+H15%))/(1+H13%)-1)*100 -> 0.51301224 | I18: =(((1+I14%)*(1+I15%))/(1+I13%)-1)*100 -> -0.77916805 | J18: =(((1+J14%)*(1+J15%))/(1+J13%)-1)*100 -> 9.2019314 | K18: =(((1+K14%)*(1+K15%))/(1+K13%)-1)*100 -> 1.3836463 | L18: =(((1+L14%)*(1+L15%))/(1+L13%)-1)*100 -> 0.69101678
B19: Weighted average interest rate (%) | C19: rw | D19: =(2.5%*D18%+(1-2.5%)*D17%)*100 -> -2.1118056 | E19: =(D16%*E18%+(1-D16%)*E17%)*100 -> -1.7889074 | F19: =(E16%*F18%+(1-E16%)*F17%)*100 -> -2.7725611 | G19: =(F16%*G18%+(1-F16%)*G17%)*100 -> -2.8181031 | H19: =(G16%*H18%+(1-G16%)*H17%)*100 -> -1.9865135 | I19: =(H16%*I18%+(1-H16%)*I17%)*100 -> 0.42159694 | J19: =(I16%*J18%+(1-I16%)*J17%)*100 -> 0.96371931 | K19: =(J16%*K18%+(1-J16%)*K17%)*100 -> 0.94226687 | L19: =(K16%*L18%+(1-K16%)*L17%)*100 -> 0.93657453
B20: Primary balance (% of GDP) | C20: pb | D20: 0.3 | E20: -1 | F20: -0.25 | G20: 0 | H20: 0.15 | I20: 0.2 | J20: 0 | K20: 0.2 | L20: 0.3
B21: Public debt (% of GDP) | C21: d | D21: 35.48 | E21: 39.83 | F21: 36.37 | G21: 32.69 | H21: 41.341034 | I21: 41.85963 | J21: 41.679464 | K21: 41.53584 | L21: 41.43757 | N21: Average Error
D22: =((1+D19%)/(1+D11%)*42.26%-D20%)*100 -> 40.058586 | E22: =((1+E19%)/(1+E11%)*42.26%-E20%)*100 -> 43.351028 | F22: =((1+F19%)/(1+F11%)*42.26%-F20%)*100 -> 39.049165 | G22: =((1+G19%)/(1+G11%)*42.26%-G20%)*100 -> 40.462138 | H22: =((1+H19%)/(1+H11%)*42.26%-H20%)*100 -> 41.341034 | I22: =((1+I19%)/(1+I11%)*42.26%-I20%)*100 -> 41.85963 | J22: =((1+J19%)/(1+J11%)*42.26%-J20%)*100 -> 41.679464 | K22: =((1+K19%)/(1+K11%)*42.26%-K20%)*100 -> 41.53584 | L22: =((1+L19%)/(1+L11%)*42.26%-L20%)*100 -> 41.43757 | N22: =AVERAGE(D23:G23) -> 4.6377293
D23: =ABS(D21-D22) -> 4.5785863 | E23: =ABS(E21-E22) -> 3.5210283 | F23: =ABS(F21-F22) -> 2.6791649 | G23: =ABS(G21-G22) -> 7.7721376
B33: Links
B34: https://www.reuters.com/markets/rates-bonds/swedens-riksbank-seen-making-half-percentage-point-rate-cut-2024-11-04/
B35: https://tradingeconomics.com/sweden/interest-rate
B36: https://tradingeconomics.com/sweden/full-year-gdp-growth
B37: https://tradingeconomics.com/sweden/inflation-gdp-deflator-annual-percent-wb-data.html
B38: https://www.statista.com/statistics/375277/gross-domestic-product-gdp-growth-rate-in-sweden/
B39: https://eur-lex.europa.eu/legal-content/EN/TXT/PDF/?uri=OJ:C_202500644
B40: https://www.riksbank.se/en-gb/statistics/interest-rates-and-exchange-rates/search-annual-and-monthly-average-exchange-rates/?a=Y&y=2019&m=Select+month&s=g130-SEKUSDPMI&fs=3#result-section
B41: https://longforecast.com/usd-to-sek
B42: https://www.riksgalden.se/en/press-and-publications/
B43: https://www.scb.se/en/
C44: 2018 | D44: 2019 | E44: 2020 | F44: 2021 | G44: 2022 | H44: 2023 | I44: 2024 | J44: 2025 | K44: 2026 | L44: 2027
B45: Exchange rate | C45: 8.6921 | D45: 9.46039 | E45: 9.20374 | F45: 8.58151 | G45: 10.12448 | H45: 10.61284 | I45: 10.56137 | J45: 11.55 | K45: 11.63 | L45: 11.63
