Workbook

Sheet Variant 1
A1: Profits per quarter | C1: 1Q | D1: 2Q | E1: 3Q | F1: 4Q | G1: 1Q | H1: 2Q | I1: 3Q | J1: 4Q | K1: 1Q | L1: 2Q | M1: 3Q | N1: 4Q | Q1: 1 Завдання
A2: Customer 1 | B2: -100 | C2: 50 | D2: =100 -> 100 | E2: =100 -> 100 | F2: =100 -> 100 | G2: =100 -> 100 | H2: =100 -> 100 | I2: =100 -> 100 | J2: =100 -> 100 | K2: =100 -> 100 | ... N2: =100 -> 100
A3: Customer 2 | E3: -100 | F3: 340 | G3: 450 | H3: 1000 | Q3: R | R3: F | S3: M
A4: Customer 3 | B4: -100 | C4: 20 | D4: 20 | E4: 20 | F4: 20 | G4: 40 | H4: 40 | I4: 40 | J4: 40 | K4: 80 | L4: 80 | M4: 80 | N4: 80 | Q4: Bad-Good | R4: Bad-Good | S4: Bad-Good
A5: Customer 4 | B5: -300 | C5: 1200 | D5: 1200 | E5: 1200
A6: Customer 5 | C6: -50 | D6: 400 | G6: 310 | H6: 380 | I6: 300 | K6: 230 | M6: 158 | N6: 152 | Q6: To determine 8 (=2*2*2) classes and describe their characteristics
A7: Customer 6 | E7: -400 | G7: 200 | H7: 200 | I7: 200 | J7: 200 | K7: 200 | L7: 200 | M7: 200 | N7: 200
A8: Customer 7 | B8: -50 | C8: 400 | F8: 400 | G8: 400 | J8: 400 | K8: 400 | N8: 400
A9: Customer 8 | B9: -50 | C9: 100 | D9: =C9+20 -> 120 | E9: =D9+20 -> 140 | F9: =E9+20 -> 160 | G9: =F9+20 -> 180 | H9: =G9+30 -> 210 | I9: =H9+30 -> 240 | J9: =I9+30 -> 270 | K9: =J9+30 -> 300 | L9: =K9+30 -> 330 | M9: =L9+30 -> 360 | N9: =M9+30 -> 390 | Q9: 2 Завдання
A10: Customer 9 | B10: -50 | C10: 560 | D10: 560 | E10: 560 | F10: 560 | G10: 560 | H10: 560
A11: Customer 10 | B11: -50 | D11: 600 | E11: =D11-25 -> 575 | F11: =E11-25 -> 550 | G11: =F11-25 -> 525 | H11: =G11-25 -> 500 | I11: =H11-25 -> 475 | J11: =I11-25 -> 450 | Q11: R | R11: F | S11: M
A12: Customer 11 | B12: -50 | C12: 80 | D12: 80 | E12: 80 | F12: 80 | G12: 80 | H12: 80 | I12: 80 | J12: 80 | K12: 80 | L12: 80 | M12: 80 | N12: 80 | P12: Score values | Q12: 1-2-3 | R12: 1-2-3 | S12: 1-2-3
A13: Customer 12 | C13: -50 | D13: 400 | G13: 310 | I13: 300 | K13: 230
A14: Customer 13 | C14: -50 | D14: 60 | E14: 80 | F14: 120 | G14: 200 | J14: 210 | P14: Weights | Q14: 0.2 | R14: 0.4 | S14: 0.4
A15: Customer 14 | C15: -50 | D15: 1410
A16: Customer 15 | B16: -100 | C16: 5 | D16: 10 | E16: 35 | F16: 74 | G16: 80 | H16: 120 | I16: 140 | J16: 145 | K16: 168 | L16: 189 | M16: 201 | Q16: To construct score values distributions
A17: Customer 16 | B17: -100 | D17: 25 | E17: 35 | F17: 45 | G17: 55 | H17: 65 | I17: 65 | J17: 65 | K17: 65 | L17: 65 | M17: 65
A18: Customer 17 | B18: -100
A19: Customer 18 | B19: -100 | Q19: 3 Завдання
A20: Customer 19 | B20: -100
A21: Customer 20 | E21: -200 | Q21: Graphs of pairs of score values (R-F), (F-M), (R-M)
A22: Customer 21 | G22: -50
A23: Customer 22 | G23: -200
A24: Customer 23 | G24: -200
A25: Customer 24 | G25: -200
A26: Customer 25 | G26: -200
A27: Customer 26 | G27: -400
A28: Customer 27 | G28: -400
A29: Customer 28 | G29: -400
A30: Customer 29 | L30: -150
A31: Customer 30 | L31: -150

Sheet Variant 2
A1: Profits per quarter | C1: 1Q | D1: 2Q | E1: 3Q | F1: 4Q | G1: 1Q | H1: 2Q | I1: 3Q | J1: 4Q | K1: 1Q | L1: 2Q | M1: 3Q | N1: 4Q | Q1: 1 Завдання | V1: Profits per quarter | W1: CAC | X1: 1 | Y1: 2 | Z1: 3 | AA1: 4 | AB1: 5 | AC1: 6 | AD1: 7 | AE1: 8 | AF1: 9 | AG1: 10 | AH1: 11 | AI1: 12 | AJ1: Recency | AK1: Frequency | AL1: Monetary | AM1: R_Group | AN1: F_Group | AO1: M_Group | AQ1: Group | AR1: Median | AS1: 33_% | AT1: 66_% | AV1: R_Group | AW1: F_Group | AX1: M_Group | AY1: Average of Recency | AZ1: Average of Frequency | BA1: Sum of Monetary
A2: Customer 1 | B2: -200 | C2: 50 | D2: =100+C2 -> 150 | E2: =100+D2 -> 250 | F2: =100+E2 -> 350 | G2: =100+F2 -> 450 | H2: =100+G2 -> 550 | I2: =100+H2 -> 650 | K2: =100 -> 100 | L2: =100 -> 100 | M2: =100 -> 100 | N2: =100 -> 100 | V2: Customer 1 | W2: -200 | X2: 50 | Y2: 150 | Z2: 250 | AA2: 350 | AB2: 450 | AC2: 550 | AD2: 650 | AF2: 100 | AG2: 100 | AH2: 100 | AI2: 100 | AJ2: {=12 - LOOKUP(2, 1/(X2:AI2<>""), $X$1:$AI$1)} -> 0 | AK2: =COUNTIF(X2:AI2,">0") -> 11 | AL2: =SUM(W2:AI2) -> 2650 | AM2: =IF(AJ2<=$AR$2,"Good","Bad") -> Good | AN2: =IF(AK2>=$AR$3,"Good","Bad") -> Good | AO2: =IF(AL2>=$AR$4,"Good","Bad") -> Good | AQ2: R | AR2: =MEDIAN(AJ2:AJ31) -> 3 | AS2: =_xlfn.PERCENTILE.INC($AJ$2:$AJ$31,0.33) -> 1.71 | AT2: =_xlfn.PERCENTILE.INC($AJ$2:$AJ$31,0.667) -> 6.343 | AV2: Bad | AW2: Bad | AX2: Bad | AY2: 8 | AZ2: 0.375 | BA2: -940
A3: Customer 2 | E3: -500 | F3: 1340 | G3: 2300 | H3: 1000 | I3: 1000 | J3: 1000 | Q3: R | R3: F | S3: M | V3: Customer 2 | Z3: -500 | AA3: 1340 | AB3: 2300 | AC3: 1000 | AD3: 1000 | AE3: 1000 | AJ3: {=12 - LOOKUP(2, 1/(X3:AI3<>""), $X$1:$AI$1)} -> 4 | AK3: =COUNTIF(X3:AI3,">0") -> 5 | AL3: =SUM(W3:AI3) -> 6140 | AM3: =IF(AJ3<=$AR$2,"Good","Bad") -> Bad | AN3: =IF(AK3>=$AR$3,"Good","Bad") -> Good | AO3: =IF(AL3>=$AR$4,"Good","Bad") -> Good | AQ3: F | AR3: =MEDIAN(AK2:AK31) -> 3.5 | AS3: =_xlfn.PERCENTILE.INC($AK$2:$AK$31,0.33) -> 0 | AT3: =_xlfn.PERCENTILE.INC($AK$2:$AK$31,0.667) -> 6.343 | AV3: Bad | AW3: Bad | AX3: Good | AY3: 9.5 | AZ3: 2 | BA3: 5140
A4: Customer 3 | B4: -100 | C4: 20 | D4: 20 | E4: 20 | F4: 20 | G4: 40 | H4: 40 | I4: 40 | J4: 40 | K4: 80 | L4: 80 | M4: 80 | N4: 80 | Q4: Bad-Good | R4: Bad-Good | S4: Bad-Good | V4: Customer 3 | W4: -100 | X4: 20 | Y4: 20 | Z4: 20 | AA4: 20 | AB4: 40 | AC4: 40 | AD4: 40 | AE4: 40 | AF4: 80 | AG4: 80 | AH4: 80 | AI4: 80 | AJ4: {=12 - LOOKUP(2, 1/(X4:AI4<>""), $X$1:$AI$1)} -> 0 | AK4: =COUNTIF(X4:AI4,">0") -> 12 | AL4: =SUM(W4:AI4) -> 460 | AM4: =IF(AJ4<=$AR$2,"Good","Bad") -> Good | AN4: =IF(AK4>=$AR$3,"Good","Bad") -> Good | AO4: =IF(AL4>=$AR$4,"Good","Bad") -> Bad | AQ4: M | AR4: =MEDIAN(AL2:AL31) -> 592.5 | AS4: =_xlfn.PERCENTILE.INC($AL$2:$AL$31,0.33) -> -71.5 | AT4: =_xlfn.PERCENTILE.INC($AL$2:$AL$31,0.667) -> 1499.751 | AV4: Bad | AW4: Good | AX4: Bad | AY4: 4 | AZ4: 5 | BA4: 570
A5: Customer 4 | B5: -100 | C5: 40 | D5: 40 | E5: 40 | F5: 20 | G5: 80 | H5: 80 | I5: 80 | J5: 40 | K5: 80 | L5: 80 | M5: 80 | N5: 80 | V5: Customer 4 | W5: -100 | X5: 40 | Y5: 40 | Z5: 40 | AA5: 20 | AB5: 80 | AC5: 80 | AD5: 80 | AE5: 40 | AF5: 80 | AG5: 80 | AH5: 80 | AI5: 80 | AJ5: {=12 - LOOKUP(2, 1/(X5:AI5<>""), $X$1:$AI$1)} -> 0 | AK5: =COUNTIF(X5:AI5,">0") -> 12 | AL5: =SUM(W5:AI5) -> 640 | AM5: =IF(AJ5<=$AR$2,"Good","Bad") -> Good | AN5: =IF(AK5>=$AR$3,"Good","Bad") -> Good | AO5: =IF(AL5>=$AR$4,"Good","Bad") -> Good | AV5: Bad | AW5: Good | AX5: Good | AY5: 4.6666667 | AZ5: 6 | BA5: 12975
A6: Customer 5 | C6: -50 | D6: 400 | E6: 400 | F6: 400 | G6: 310 | H6: 380 | I6: 300 | J6: 300 | K6: 300 | L6: 300 | M6: 300 | N6: 300 | Q6: To determine 8 (=2*2*2) classes and describe their characteristics | V6: Customer 5 | X6: -50 | Y6: 400 | Z6: 400 | AA6: 400 | AB6: 310 | AC6: 380 | AD6: 300 | AE6: 300 | AF6: 300 | AG6: 300 | AH6: 300 | AI6: 300 | AJ6: {=12 - LOOKUP(2, 1/(X6:AI6<>""), $X$1:$AI$1)} -> 0 | AK6: =COUNTIF(X6:AI6,">0") -> 11 | AL6: =SUM(W6:AI6) -> 3640 | AM6: =IF(AJ6<=$AR$2,"Good","Bad") -> Good | AN6: =IF(AK6>=$AR$3,"Good","Bad") -> Good | AO6: =IF(AL6>=$AR$4,"Good","Bad") -> Good | AV6: Good | AW6: Bad | AX6: Bad | AY6: 3 | AZ6: 0 | BA6: -1500
A7: Customer 6 | B7: -400 | C7: 150 | D7: 150 | E7: 150 | F7: 150 | G7: 200 | H7: 200 | I7: 200 | J7: 200 | K7: 200 | L7: 200 | M7: 200 | N7: 200 | V7: Customer 6 | W7: -400 | X7: 150 | Y7: 150 | Z7: 150 | AA7: 150 | AB7: 200 | AC7: 200 | AD7: 200 | AE7: 200 | AF7: 200 | AG7: 200 | AH7: 200 | AI7: 200 | AJ7: {=12 - LOOKUP(2, 1/(X7:AI7<>""), $X$1:$AI$1)} -> 0 | AK7: =COUNTIF(X7:AI7,">0") -> 12 | AL7: =SUM(W7:AI7) -> 1800 | AM7: =IF(AJ7<=$AR$2,"Good","Bad") -> Good | AN7: =IF(AK7>=$AR$3,"Good","Bad") -> Good | AO7: =IF(AL7>=$AR$4,"Good","Bad") -> Good | AV7: Good | AW7: Good | AX7: Bad | AY7: 0 | AZ7: 12 | BA7: 460
A8: Customer 7 | B8: -50 | C8: 400 | F8: 400 | G8: 400 | J8: 400 | K8: 400 | N8: 400 | V8: Customer 7 | W8: -50 | X8: 400 | AA8: 400 | AB8: 400 | AE8: 400 | AF8: 400 | AI8: 400 | AJ8: {=12 - LOOKUP(2, 1/(X8:AI8<>""), $X$1:$AI$1)} -> 0 | AK8: =COUNTIF(X8:AI8,">0") -> 6 | AL8: =SUM(W8:AI8) -> 2350 | AM8: =IF(AJ8<=$AR$2,"Good","Bad") -> Good | AN8: =IF(AK8>=$AR$3,"Good","Bad") -> Good | AO8: =IF(AL8>=$AR$4,"Good","Bad") -> Good | AV8: Good | AW8: Good | AX8: Good | AY8: 0.3 | AZ8: 10.3 | BA8: 20998
A9: Customer 8 | B9: -400 | C9: 200 | D9: =C9+60 -> 260 | E9: =D9+60 -> 320 | F9: =E9+60 -> 380 | G9: =F9+60 -> 440 | H9: =G9+60 -> 500 | I9: =H9+60 -> 560 | J9: =I9+60 -> 620 | K9: =J9+60 -> 680 | ... N9: =M9+60 -> 860 | Q9: 2 Завдання | V9: Customer 8 | W9: -400 | X9: 200 | Y9: 260 | Z9: 320 | AA9: 380 | AB9: 440 | AC9: 500 | AD9: 560 | AE9: 620 | AF9: 680 | AG9: 740 | AH9: 800 | AI9: 860 | AJ9: {=12 - LOOKUP(2, 1/(X9:AI9<>""), $X$1:$AI$1)} -> 0 | AK9: =COUNTIF(X9:AI9,">0") -> 12 | AL9: =SUM(W9:AI9) -> 5960 | AM9: =IF(AJ9<=$AR$2,"Good","Bad") -> Good | AN9: =IF(AK9>=$AR$3,"Good","Bad") -> Good | AO9: =IF(AL9>=$AR$4,"Good","Bad") -> Good
A10: Customer 9 | B10: -100 | C10: 560 | D10: 560 | E10: 560 | F10: 560 | G10: 560 | H10: 560 | V10: Customer 9 | W10: -100 | X10: 560 | Y10: 560 | Z10: 560 | AA10: 560 | AB10: 560 | AC10: 560 | AJ10: {=12 - LOOKUP(2, 1/(X10:AI10<>""), $X$1:$AI$1)} -> 6 | AK10: =COUNTIF(X10:AI10,">0") -> 6 | AL10: =SUM(W10:AI10) -> 3260 | AM10: =IF(AJ10<=$AR$2,"Good","Bad") -> Bad | AN10: =IF(AK10>=$AR$3,"Good","Bad") -> Good | AO10: =IF(AL10>=$AR$4,"Good","Bad") -> Good
A11: Customer 10 | B11: -100 | D11: 600 | E11: =D11-25 -> 575 | F11: =E11-25 -> 550 | G11: =F11-25 -> 525 | H11: =G11-25 -> 500 | I11: =H11-25 -> 475 | J11: =I11-25 -> 450 | Q11: R | R11: F | S11: M | V11: Customer 10 | W11: -100 | Y11: 600 | Z11: 575 | AA11: 550 | AB11: 525 | AC11: 500 | AD11: 475 | AE11: 450 | AJ11: {=12 - LOOKUP(2, 1/(X11:AI11<>""), $X$1:$AI$1)} -> 4 | AK11: =COUNTIF(X11:AI11,">0") -> 7 | AL11: =SUM(W11:AI11) -> 3575 | AM11: =IF(AJ11<=$AR$2,"Good","Bad") -> Bad | AN11: =IF(AK11>=$AR$3,"Good","Bad") -> Good | AO11: =IF(AL11>=$AR$4,"Good","Bad") -> Good | AV11: R_Group | AW11: F_Group | AX11: M_Group | AY11: Average of Recency | AZ11: Average of Frequency | BA11: Sum of Monetary
A12: Customer 11 | B12: -100 | C12: 80 | D12: 80 | E12: 80 | F12: 80 | G12: 80 | H12: 80 | I12: 80 | J12: 80 | K12: 80 | L12: 80 | M12: 80 | N12: 80 | P12: Score values | Q12: 1-2-3 | R12: 1-2-3 | S12: 1-2-3 | V12: Customer 11 | W12: -100 | X12: 80 | Y12: 80 | Z12: 80 | AA12: 80 | AB12: 80 | AC12: 80 | AD12: 80 | AE12: 80 | AF12: 80 | AG12: 80 | AH12: 80 | AI12: 80 | AJ12: {=12 - LOOKUP(2, 1/(X12:AI12<>""), $X$1:$AI$1)} -> 0 | AK12: =COUNTIF(X12:AI12,">0") -> 12 | AL12: =SUM(W12:AI12) -> 860 | AM12: =IF(AJ12<=$AR$2,"Good","Bad") -> Good | AN12: =IF(AK12>=$AR$3,"Good","Bad") -> Good | AO12: =IF(AL12>=$AR$4,"Good","Bad") -> Good | AV12: Bad | AW12: Bad | AX12: Bad | AY12: 8 | AZ12: 0.375 | BA12: -940
A13: Customer 12 | B13: -100 | D13: 400 | G13: 310 | I13: 300 | K13: 230 | V13: Customer 12 | W13: -100 | Y13: 400 | AB13: 310 | AD13: 300 | AF13: 230 | AJ13: {=12 - LOOKUP(2, 1/(X13:AI13<>""), $X$1:$AI$1)} -> 3 | AK13: =COUNTIF(X13:AI13,">0") -> 4 | AL13: =SUM(W13:AI13) -> 1140 | AM13: =IF(AJ13<=$AR$2,"Good","Bad") -> Good | AN13: =IF(AK13>=$AR$3,"Good","Bad") -> Good | AO13: =IF(AL13>=$AR$4,"Good","Bad") -> Good | AV13: Bad | AW13: Bad | AX13: Good | AY13: 9.5 | AZ13: 2 | BA13: 5140
A14: Customer 13 | B14: -100 | D14: 60 | E14: 80 | F14: 120 | G14: 200 | J14: 210 | P14: Weights | Q14: 0.2 | R14: 0.4 | S14: 0.4 | V14: Customer 13 | W14: -100 | Y14: 60 | Z14: 80 | AA14: 120 | AB14: 200 | AE14: 210 | AJ14: {=12 - LOOKUP(2, 1/(X14:AI14<>""), $X$1:$AI$1)} -> 4 | AK14: =COUNTIF(X14:AI14,">0") -> 5 | AL14: =SUM(W14:AI14) -> 570 | AM14: =IF(AJ14<=$AR$2,"Good","Bad") -> Bad | AN14: =IF(AK14>=$AR$3,"Good","Bad") -> Good | AO14: =IF(AL14>=$AR$4,"Good","Bad") -> Bad | AV14: Bad | AW14: Good | AX14: Bad | AY14: 4 | AZ14: 5 | BA14: 570
A15: Customer 14 | C15: -50 | D15: 1890 | V15: Customer 14 | X15: -50 | Y15: 1890 | AJ15: {=12 - LOOKUP(2, 1/(X15:AI15<>""), $X$1:$AI$1)} -> 10 | AK15: =COUNTIF(X15:AI15,">0") -> 1 | AL15: =SUM(W15:AI15) -> 1840 | AM15: =IF(AJ15<=$AR$2,"Good","Bad") -> Bad | AN15: =IF(AK15>=$AR$3,"Good","Bad") -> Bad | AO15: =IF(AL15>=$AR$4,"Good","Bad") -> Good | AV15: Bad | AW15: Good | AX15: Good | AY15: 4.6666667 | AZ15: 6 | BA15: 12975
A16: Customer 15 | B16: -100 | C16: 89 | D16: 10 | E16: 35 | F16: 65 | G16: 80 | H16: 120 | I16: 140 | J16: 145 | K16: 168 | L16: 189 | M16: 201 | N16: 201 | Q16: To construct score values distributions | V16: Customer 15 | W16: -100 | X16: 89 | Y16: 10 | Z16: 35 | AA16: 65 | AB16: 80 | AC16: 120 | AD16: 140 | AE16: 145 | AF16: 168 | AG16: 189 | AH16: 201 | AI16: 201 | AJ16: {=12 - LOOKUP(2, 1/(X16:AI16<>""), $X$1:$AI$1)} -> 0 | AK16: =COUNTIF(X16:AI16,">0") -> 12 | AL16: =SUM(W16:AI16) -> 1343 | AM16: =IF(AJ16<=$AR$2,"Good","Bad") -> Good | AN16: =IF(AK16>=$AR$3,"Good","Bad") -> Good | AO16: =IF(AL16>=$AR$4,"Good","Bad") -> Good | AV16: Good | AW16: Bad | AX16: Bad | AY16: 3 | AZ16: 0 | BA16: -1500
A17: Customer 16 | B17: -100 | D17: 25 | E17: 35 | F17: 45 | G17: 55 | H17: 80 | I17: 80 | J17: 80 | K17: 75 | L17: 80 | M17: 80 | N17: 80 | V17: Customer 16 | W17: -100 | Y17: 25 | Z17: 35 | AA17: 45 | AB17: 55 | AC17: 80 | AD17: 80 | AE17: 80 | AF17: 75 | AG17: 80 | AH17: 80 | AI17: 80 | AJ17: {=12 - LOOKUP(2, 1/(X17:AI17<>""), $X$1:$AI$1)} -> 0 | AK17: =COUNTIF(X17:AI17,">0") -> 11 | AL17: =SUM(W17:AI17) -> 615 | AM17: =IF(AJ17<=$AR$2,"Good","Bad") -> Good | AN17: =IF(AK17>=$AR$3,"Good","Bad") -> Good | AO17: =IF(AL17>=$AR$4,"Good","Bad") -> Good | AV17: Good | AW17: Good | AX17: Bad | AY17: 0 | AZ17: 12 | BA17: 460
A18: Customer 17 | B18: -300 | C18: 1200 | D18: 1200 | E18: 1200 | V18: Customer 17 | W18: -300 | X18: 1200 | Y18: 1200 | Z18: 1200 | AJ18: {=12 - LOOKUP(2, 1/(X18:AI18<>""), $X$1:$AI$1)} -> 9 | AK18: =COUNTIF(X18:AI18,">0") -> 3 | AL18: =SUM(W18:AI18) -> 3300 | AM18: =IF(AJ18<=$AR$2,"Good","Bad") -> Bad | AN18: =IF(AK18>=$AR$3,"Good","Bad") -> Bad | AO18: =IF(AL18>=$AR$4,"Good","Bad") -> Good | AV18: Good | AW18: Good | AX18: Good | AY18: 0.3 | AZ18: 10.3 | BA18: 20998
A19: Customer 18 | B19: -100 | C19: 90 | Q19: 3 Завдання | V19: Customer 18 | W19: -100 | X19: 90 | AJ19: {=12 - LOOKUP(2, 1/(X19:AI19<>""), $X$1:$AI$1)} -> 11 | AK19: =COUNTIF(X19:AI19,">0") -> 1 | AL19: =SUM(W19:AI19) -> -10 | AM19: =IF(AJ19<=$AR$2,"Good","Bad") -> Bad | AN19: =IF(AK19>=$AR$3,"Good","Bad") -> Bad | AO19: =IF(AL19>=$AR$4,"Good","Bad") -> Bad
A20: Customer 19 | B20: -100 | D20: 60 | E20: 60 | V20: Customer 19 | W20: -100 | Y20: 60 | Z20: 60 | AJ20: {=12 - LOOKUP(2, 1/(X20:AI20<>""), $X$1:$AI$1)} -> 9 | AK20: =COUNTIF(X20:AI20,">0") -> 2 | AL20: =SUM(W20:AI20) -> 20 | AM20: =IF(AJ20<=$AR$2,"Good","Bad") -> Bad | AN20: =IF(AK20>=$AR$3,"Good","Bad") -> Bad | AO20: =IF(AL20>=$AR$4,"Good","Bad") -> Bad
A21: Customer 20 | E21: -100 | Q21: Graphs of pairs of score values (R-F), (F-M), (R-M) | V21: Customer 20 | Z21: -100 | AJ21: {=12 - LOOKUP(2, 1/(X21:AI21<>""), $X$1:$AI$1)} -> 9 | AK21: =COUNTIF(X21:AI21,">0") -> 0 | AL21: =SUM(W21:AI21) -> -100 | AM21: =IF(AJ21<=$AR$2,"Good","Bad") -> Bad | AN21: =IF(AK21>=$AR$3,"Good","Bad") -> Bad | AO21: =IF(AL21>=$AR$4,"Good","Bad") -> Bad
A22: Customer 21 | G22: -50 | V22: Customer 21 | AB22: -50 | AJ22: {=12 - LOOKUP(2, 1/(X22:AI22<>""), $X$1:$AI$1)} -> 7 | AK22: =COUNTIF(X22:AI22,">0") -> 0 | AL22: =SUM(W22:AI22) -> -50 | AM22: =IF(AJ22<=$AR$2,"Good","Bad") -> Bad | AN22: =IF(AK22>=$AR$3,"Good","Bad") -> Bad | AO22: =IF(AL22>=$AR$4,"Good","Bad") -> Bad
A23: Customer 22 | G23: -200 | V23: Customer 22 | AB23: -200 | AJ23: {=12 - LOOKUP(2, 1/(X23:AI23<>""), $X$1:$AI$1)} -> 7 | AK23: =COUNTIF(X23:AI23,">0") -> 0 | AL23: =SUM(W23:AI23) -> -200 | AM23: =IF(AJ23<=$AR$2,"Good","Bad") -> Bad | AN23: =IF(AK23>=$AR$3,"Good","Bad") -> Bad | AO23: =IF(AL23>=$AR$4,"Good","Bad") -> Bad
A24: Customer 23 | G24: -200 | V24: Customer 23 | AB24: -200 | AJ24: {=12 - LOOKUP(2, 1/(X24:AI24<>""), $X$1:$AI$1)} -> 7 | AK24: =COUNTIF(X24:AI24,">0") -> 0 | AL24: =SUM(W24:AI24) -> -200 | AM24: =IF(AJ24<=$AR$2,"Good","Bad") -> Bad | AN24: =IF(AK24>=$AR$3,"Good","Bad") -> Bad | AO24: =IF(AL24>=$AR$4,"Good","Bad") -> Bad
A25: Customer 24 | G25: -200 | V25: Customer 24 | AB25: -200 | AJ25: {=12 - LOOKUP(2, 1/(X25:AI25<>""), $X$1:$AI$1)} -> 7 | AK25: =COUNTIF(X25:AI25,">0") -> 0 | AL25: =SUM(W25:AI25) -> -200 | AM25: =IF(AJ25<=$AR$2,"Good","Bad") -> Bad | AN25: =IF(AK25>=$AR$3,"Good","Bad") -> Bad | AO25: =IF(AL25>=$AR$4,"Good","Bad") -> Bad
A26: Customer 25 | G26: -200 | V26: Customer 25 | AB26: -200 | AJ26: {=12 - LOOKUP(2, 1/(X26:AI26<>""), $X$1:$AI$1)} -> 7 | AK26: =COUNTIF(X26:AI26,">0") -> 0 | AL26: =SUM(W26:AI26) -> -200 | AM26: =IF(AJ26<=$AR$2,"Good","Bad") -> Bad | AN26: =IF(AK26>=$AR$3,"Good","Bad") -> Bad | AO26: =IF(AL26>=$AR$4,"Good","Bad") -> Bad
A27: Customer 26 | K27: -300 | V27: Customer 26 | AF27: -300 | AJ27: {=12 - LOOKUP(2, 1/(X27:AI27<>""), $X$1:$AI$1)} -> 3 | AK27: =COUNTIF(X27:AI27,">0") -> 0 | AL27: =SUM(W27:AI27) -> -300 | AM27: =IF(AJ27<=$AR$2,"Good","Bad") -> Good | AN27: =IF(AK27>=$AR$3,"Good","Bad") -> Bad | AO27: =IF(AL27>=$AR$4,"Good","Bad") -> Bad
A28: Customer 27 | K28: -300 | V28: Customer 27 | AF28: -300 | AJ28: {=12 - LOOKUP(2, 1/(X28:AI28<>""), $X$1:$AI$1)} -> 3 | AK28: =COUNTIF(X28:AI28,">0") -> 0 | AL28: =SUM(W28:AI28) -> -300 | AM28: =IF(AJ28<=$AR$2,"Good","Bad") -> Good | AN28: =IF(AK28>=$AR$3,"Good","Bad") -> Bad | AO28: =IF(AL28>=$AR$4,"Good","Bad") -> Bad
A29: Customer 28 | K29: -300 | V29: Customer 28 | AF29: -300 | AJ29: {=12 - LOOKUP(2, 1/(X29:AI29<>""), $X$1:$AI$1)} -> 3 | AK29: =COUNTIF(X29:AI29,">0") -> 0 | AL29: =SUM(W29:AI29) -> -300 | AM29: =IF(AJ29<=$AR$2,"Good","Bad") -> Good | AN29: =IF(AK29>=$AR$3,"Good","Bad") -> Bad | AO29: =IF(AL29>=$AR$4,"Good","Bad") -> Bad
A30: Customer 29 | K30: -300 | V30: Customer 29 | AF30: -300 | AJ30: {=12 - LOOKUP(2, 1/(X30:AI30<>""), $X$1:$AI$1)} -> 3 | AK30: =COUNTIF(X30:AI30,">0") -> 0 | AL30: =SUM(W30:AI30) -> -300 | AM30: =IF(AJ30<=$AR$2,"Good","Bad") -> Good | AN30: =IF(AK30>=$AR$3,"Good","Bad") -> Bad | AO30: =IF(AL30>=$AR$4,"Good","Bad") -> Bad
A31: Customer 30 | K31: -300 | V31: Customer 30 | AF31: -300 | AJ31: {=12 - LOOKUP(2, 1/(X31:AI31<>""), $X$1:$AI$1)} -> 3 | AK31: =COUNTIF(X31:AI31,">0") -> 0 | AL31: =SUM(W31:AI31) -> -300 | AM31: =IF(AJ31<=$AR$2,"Good","Bad") -> Good | AN31: =IF(AK31>=$AR$3,"Good","Bad") -> Bad | AO31: =IF(AL31>=$AR$4,"Good","Bad") -> Bad
A33: Note: red colored values of CAC
V34: Profits per quarter | W34: CAC | X34: 1 | Y34: 2 | Z34: 3 | AA34: 4 | AB34: 5 | AC34: 6 | AD34: 7 | AE34: 8 | AF34: 9 | AG34: 10 | AH34: 11 | AI34: 12 | AJ34: Recency | AK34: Frequency | AL34: Monetary | AM34: R_Group | AN34: F_Group | AO34: M_Group | AP34: Score_Value | AS34: Bin | AT34: Frequency | BA34: Bins | BD34: Bins | BE34: Frequency
V35: Customer 1 | W35: -200 | X35: 50 | Y35: 150 | Z35: 250 | AA35: 350 | AB35: 450 | AC35: 550 | AD35: 650 | AF35: 100 | AG35: 100 | AH35: 100 | AI35: 100 | AJ35: 0 | AK35: 11 | AL35: 2650 | AM35: =IF(AJ35<=$AS$2,3,IF(AJ35<=$AT$2,2,1)) -> 3 | AN35: =IF(AK35>=$AT$3,3,IF(AK35>$AS$3,2,1)) -> 3 | AO35: =IF(AL35>=$AT$4,3,IF(AL35>=$AS$4,2,1)) -> 3 | AP35: =0.2*AM35+0.4*'Variant 2'!AN35+0.4*'Variant 2'!AO35 -> 3 | AS35: 1 | AT35: 5 | BA35: 1 | BD35: 1 | BE35: 5
V36: Customer 2 | Z36: -500 | AA36: 1340 | AB36: 2300 | AC36: 1000 | AD36: 1000 | AE36: 1000 | AJ36: 4 | AK36: 5 | AL36: 6140 | AM36: =IF(AJ36<=$AS$2,3,IF(AJ36<=$AT$2,2,1)) -> 2 | AN36: =IF(AK36>=$AT$3,3,IF(AK36>$AS$3,2,1)) -> 2 | AO36: =IF(AL36>=$AT$4,3,IF(AL36>=$AS$4,2,1)) -> 3 | AP36: =0.2*AM36+0.4*'Variant 2'!AN36+0.4*'Variant 2'!AO36 -> 2.4 | AS36: 1.4 | AT36: 6 | BA36: 2 | BD36: (1-2] | BE36: 10
V37: Customer 3 | W37: -100 | X37: 20 | Y37: 20 | Z37: 20 | AA37: 20 | AB37: 40 | AC37: 40 | AD37: 40 | AE37: 40 | AF37: 80 | AG37: 80 | AH37: 80 | AI37: 80 | AJ37: 0 | AK37: 12 | AL37: 460 | AM37: =IF(AJ37<=$AS$2,3,IF(AJ37<=$AT$2,2,1)) -> 3 | AN37: =IF(AK37>=$AT$3,3,IF(AK37>$AS$3,2,1)) -> 3 | AO37: =IF(AL37>=$AT$4,3,IF(AL37>=$AS$4,2,1)) -> 2 | AP37: =0.2*AM37+0.4*'Variant 2'!AN37+0.4*'Variant 2'!AO37 -> 2.6 | AS37: 1.8 | AT37: 2 | BA37: 3 | BD37: (2-3) | BE37: 11
V38: Customer 4 | W38: -100 | X38: 40 | Y38: 40 | Z38: 40 | AA38: 20 | AB38: 80 | AC38: 80 | AD38: 80 | AE38: 40 | AF38: 80 | AG38: 80 | AH38: 80 | AI38: 80 | AJ38: 0 | AK38: 12 | AL38: 640 | AM38: =IF(AJ38<=$AS$2,3,IF(AJ38<=$AT$2,2,1)) -> 3 | AN38: =IF(AK38>=$AT$3,3,IF(AK38>$AS$3,2,1)) -> 3 | AO38: =IF(AL38>=$AT$4,3,IF(AL38>=$AS$4,2,1)) -> 2 | AP38: =0.2*AM38+0.4*'Variant 2'!AN38+0.4*'Variant 2'!AO38 -> 2.6 | AS38: 2.2 | AT38: 4 | BD38: 3 | BE38: 4
V39: Customer 5 | X39: -50 | Y39: 400 | Z39: 400 | AA39: 400 | AB39: 310 | AC39: 380 | AD39: 300 | AE39: 300 | AF39: 300 | AG39: 300 | AH39: 300 | AI39: 300 | AJ39: 0 | AK39: 11 | AL39: 3640 | AM39: =IF(AJ39<=$AS$2,3,IF(AJ39<=$AT$2,2,1)) -> 3 | AN39: =IF(AK39>=$AT$3,3,IF(AK39>$AS$3,2,1)) -> 3 | AO39: =IF(AL39>=$AT$4,3,IF(AL39>=$AS$4,2,1)) -> 3 | AP39: =0.2*AM39+0.4*'Variant 2'!AN39+0.4*'Variant 2'!AO39 -> 3 | AS39: 2.6 | AT39: 8
V40: Customer 6 | W40: -400 | X40: 150 | Y40: 150 | Z40: 150 | AA40: 150 | AB40: 200 | AC40: 200 | AD40: 200 | AE40: 200 | AF40: 200 | AG40: 200 | AH40: 200 | AI40: 200 | AJ40: 0 | AK40: 12 | AL40: 1800 | AM40: =IF(AJ40<=$AS$2,3,IF(AJ40<=$AT$2,2,1)) -> 3 | AN40: =IF(AK40>=$AT$3,3,IF(AK40>$AS$3,2,1)) -> 3 | AO40: =IF(AL40>=$AT$4,3,IF(AL40>=$AS$4,2,1)) -> 3 | AP40: =0.2*AM40+0.4*'Variant 2'!AN40+0.4*'Variant 2'!AO40 -> 3 | AS40: More | AT40: 5
V41: Customer 7 | W41: -50 | X41: 400 | AA41: 400 | AB41: 400 | AE41: 400 | AF41: 400 | AI41: 400 | AJ41: 0 | AK41: 6 | AL41: 2350 | AM41: =IF(AJ41<=$AS$2,3,IF(AJ41<=$AT$2,2,1)) -> 3 | AN41: =IF(AK41>=$AT$3,3,IF(AK41>$AS$3,2,1)) -> 2 | AO41: =IF(AL41>=$AT$4,3,IF(AL41>=$AS$4,2,1)) -> 3 | AP41: =0.2*AM41+0.4*'Variant 2'!AN41+0.4*'Variant 2'!AO41 -> 2.6
...
